2018-10-29 14:37:15,607 ERROR: Exception on / [GET] [in c:\users\admin\appdata\local\programs\python\python36\lib\site-packages\flask\app.py:1761]
Traceback (most recent call last):
  File "c:\users\admin\appdata\local\programs\python\python36\lib\site-packages\flask\app.py", line 2292, in wsgi_app
    response = self.full_dispatch_request()
  File "c:\users\admin\appdata\local\programs\python\python36\lib\site-packages\flask\app.py", line 1815, in full_dispatch_request
    rv = self.handle_user_exception(e)
  File "c:\users\admin\appdata\local\programs\python\python36\lib\site-packages\flask\app.py", line 1718, in handle_user_exception
    reraise(exc_type, exc_value, tb)
  File "c:\users\admin\appdata\local\programs\python\python36\lib\site-packages\flask\_compat.py", line 35, in reraise
    raise value
  File "c:\users\admin\appdata\local\programs\python\python36\lib\site-packages\flask\app.py", line 1811, in full_dispatch_request
    rv = self.preprocess_request()
  File "c:\users\admin\appdata\local\programs\python\python36\lib\site-packages\flask\app.py", line 2087, in preprocess_request
    rv = func()
  File "C:\Users\admin\Desktop\flask\mega_blog\app\main\views.py", line 109, in before_request
    g.locale = str(get_locale())
NameError: name 'get_locale' is not defined
2018-10-29 14:38:21,777 INFO: Microblog startup [in C:\Users\admin\Desktop\flask\mega_blog\app\__init__.py:58]
2018-10-29 14:38:28,754 ERROR: Exception on / [GET] [in c:\users\admin\appdata\local\programs\python\python36\lib\site-packages\flask\app.py:1761]
Traceback (most recent call last):
  File "c:\users\admin\appdata\local\programs\python\python36\lib\site-packages\flask\app.py", line 2292, in wsgi_app
    response = self.full_dispatch_request()
  File "c:\users\admin\appdata\local\programs\python\python36\lib\site-packages\flask\app.py", line 1815, in full_dispatch_request
    rv = self.handle_user_exception(e)
  File "c:\users\admin\appdata\local\programs\python\python36\lib\site-packages\flask\app.py", line 1718, in handle_user_exception
    reraise(exc_type, exc_value, tb)
  File "c:\users\admin\appdata\local\programs\python\python36\lib\site-packages\flask\_compat.py", line 35, in reraise
    raise value
  File "c:\users\admin\appdata\local\programs\python\python36\lib\site-packages\flask\app.py", line 1811, in full_dispatch_request
    rv = self.preprocess_request()
  File "c:\users\admin\appdata\local\programs\python\python36\lib\site-packages\flask\app.py", line 2087, in preprocess_request
    rv = func()
  File "C:\Users\admin\Desktop\flask\mega_blog\app\main\views.py", line 106, in before_request
    current_user.last_seen = datetime.utcnow()
NameError: name 'datetime' is not defined
2018-10-29 14:38:51,701 ERROR: Exception on / [GET] [in c:\users\admin\appdata\local\programs\python\python36\lib\site-packages\flask\app.py:1761]
Traceback (most recent call last):
  File "c:\users\admin\appdata\local\programs\python\python36\lib\site-packages\flask\app.py", line 2292, in wsgi_app
    response = self.full_dispatch_request()
  File "c:\users\admin\appdata\local\programs\python\python36\lib\site-packages\flask\app.py", line 1815, in full_dispatch_request
    rv = self.handle_user_exception(e)
  File "c:\users\admin\appdata\local\programs\python\python36\lib\site-packages\flask\app.py", line 1718, in handle_user_exception
    reraise(exc_type, exc_value, tb)
  File "c:\users\admin\appdata\local\programs\python\python36\lib\site-packages\flask\_compat.py", line 35, in reraise
    raise value
  File "c:\users\admin\appdata\local\programs\python\python36\lib\site-packages\flask\app.py", line 1811, in full_dispatch_request
    rv = self.preprocess_request()
  File "c:\users\admin\appdata\local\programs\python\python36\lib\site-packages\flask\app.py", line 2087, in preprocess_request
    rv = func()
  File "C:\Users\admin\Desktop\flask\mega_blog\app\main\views.py", line 106, in before_request
    if current_user.is_authenticated:
NameError: name 'datetime' is not defined
2018-10-29 14:38:54,102 ERROR: Exception on / [GET] [in c:\users\admin\appdata\local\programs\python\python36\lib\site-packages\flask\app.py:1761]
Traceback (most recent call last):
  File "c:\users\admin\appdata\local\programs\python\python36\lib\site-packages\flask\app.py", line 2292, in wsgi_app
    response = self.full_dispatch_request()
  File "c:\users\admin\appdata\local\programs\python\python36\lib\site-packages\flask\app.py", line 1815, in full_dispatch_request
    rv = self.handle_user_exception(e)
  File "c:\users\admin\appdata\local\programs\python\python36\lib\site-packages\flask\app.py", line 1718, in handle_user_exception
    reraise(exc_type, exc_value, tb)
  File "c:\users\admin\appdata\local\programs\python\python36\lib\site-packages\flask\_compat.py", line 35, in reraise
    raise value
  File "c:\users\admin\appdata\local\programs\python\python36\lib\site-packages\flask\app.py", line 1811, in full_dispatch_request
    rv = self.preprocess_request()
  File "c:\users\admin\appdata\local\programs\python\python36\lib\site-packages\flask\app.py", line 2087, in preprocess_request
    rv = func()
  File "C:\Users\admin\Desktop\flask\mega_blog\app\main\views.py", line 106, in before_request
    if current_user.is_authenticated:
NameError: name 'datetime' is not defined
2018-10-29 14:38:59,717 INFO: Microblog startup [in C:\Users\admin\Desktop\flask\mega_blog\app\__init__.py:58]
2018-10-29 14:39:00,912 ERROR: Exception on / [GET] [in c:\users\admin\appdata\local\programs\python\python36\lib\site-packages\flask\app.py:1761]
Traceback (most recent call last):
  File "c:\users\admin\appdata\local\programs\python\python36\lib\site-packages\flask\app.py", line 2292, in wsgi_app
    response = self.full_dispatch_request()
  File "c:\users\admin\appdata\local\programs\python\python36\lib\site-packages\flask\app.py", line 1815, in full_dispatch_request
    rv = self.handle_user_exception(e)
  File "c:\users\admin\appdata\local\programs\python\python36\lib\site-packages\flask\app.py", line 1718, in handle_user_exception
    reraise(exc_type, exc_value, tb)
  File "c:\users\admin\appdata\local\programs\python\python36\lib\site-packages\flask\_compat.py", line 35, in reraise
    raise value
  File "c:\users\admin\appdata\local\programs\python\python36\lib\site-packages\flask\app.py", line 1813, in full_dispatch_request
    rv = self.dispatch_request()
  File "c:\users\admin\appdata\local\programs\python\python36\lib\site-packages\flask\app.py", line 1799, in dispatch_request
    return self.view_functions[rule.endpoint](**req.view_args)
  File "c:\users\admin\appdata\local\programs\python\python36\lib\site-packages\flask_login\utils.py", line 261, in decorated_view
    return func(*args, **kwargs)
  File "C:\Users\admin\Desktop\flask\mega_blog\app\main\views.py", line 24, in index
    posts = current_user.followed_posts().paginate(page, app.config['POSTS_PER_PAGE'], False)
NameError: name 'app' is not defined
2018-10-29 14:40:26,233 INFO: Microblog startup [in C:\Users\admin\Desktop\flask\mega_blog\app\__init__.py:58]
2018-10-29 14:42:43,524 INFO: Microblog startup [in C:\Users\admin\Desktop\flask\mega_blog\app\__init__.py:58]
