2018-10-29 14:42:47,337 ERROR: Exception on /index [GET] [in c:\users\admin\appdata\local\programs\python\python36\lib\site-packages\flask\app.py:1761]
Traceback (most recent call last):
  File "c:\users\admin\appdata\local\programs\python\python36\lib\site-packages\flask\app.py", line 2292, in wsgi_app
    response = self.full_dispatch_request()
  File "c:\users\admin\appdata\local\programs\python\python36\lib\site-packages\flask\app.py", line 1815, in full_dispatch_request
    rv = self.handle_user_exception(e)
  File "c:\users\admin\appdata\local\programs\python\python36\lib\site-packages\flask\app.py", line 1718, in handle_user_exception
    reraise(exc_type, exc_value, tb)
  File "c:\users\admin\appdata\local\programs\python\python36\lib\site-packages\flask\_compat.py", line 35, in reraise
    raise value
  File "c:\users\admin\appdata\local\programs\python\python36\lib\site-packages\flask\app.py", line 1813, in full_dispatch_request
    rv = self.dispatch_request()
  File "c:\users\admin\appdata\local\programs\python\python36\lib\site-packages\flask\app.py", line 1799, in dispatch_request
    return self.view_functions[rule.endpoint](**req.view_args)
  File "c:\users\admin\appdata\local\programs\python\python36\lib\site-packages\flask_login\utils.py", line 261, in decorated_view
    return func(*args, **kwargs)
  File "C:\Users\admin\Desktop\flask\mega_blog\app\main\views.py", line 30, in index
    prev_url=prev_url)
  File "c:\users\admin\appdata\local\programs\python\python36\lib\site-packages\flask\templating.py", line 135, in render_template
    context, ctx.app)
  File "c:\users\admin\appdata\local\programs\python\python36\lib\site-packages\flask\templating.py", line 117, in _render
    rv = template.render(context)
  File "c:\users\admin\appdata\local\programs\python\python36\lib\site-packages\jinja2\asyncsupport.py", line 76, in render
    return original_render(self, *args, **kwargs)
  File "c:\users\admin\appdata\local\programs\python\python36\lib\site-packages\jinja2\environment.py", line 1008, in render
    return self.environment.handle_exception(exc_info, True)
  File "c:\users\admin\appdata\local\programs\python\python36\lib\site-packages\jinja2\environment.py", line 780, in handle_exception
    reraise(exc_type, exc_value, tb)
  File "c:\users\admin\appdata\local\programs\python\python36\lib\site-packages\jinja2\_compat.py", line 37, in reraise
    raise value.with_traceback(tb)
  File "C:\Users\admin\Desktop\flask\mega_blog\app\templates\index.html", line 1, in top-level template code
    {% extends "base.html" %}
  File "C:\Users\admin\Desktop\flask\mega_blog\app\templates\base.html", line 20, in top-level template code
    <form action="{{url_for('main.search')}}">
  File "c:\users\admin\appdata\local\programs\python\python36\lib\site-packages\flask\helpers.py", line 356, in url_for
    return appctx.app.handle_url_build_error(error, endpoint, values)
  File "c:\users\admin\appdata\local\programs\python\python36\lib\site-packages\flask\app.py", line 2061, in handle_url_build_error
    reraise(exc_type, exc_value, tb)
  File "c:\users\admin\appdata\local\programs\python\python36\lib\site-packages\flask\_compat.py", line 35, in reraise
    raise value
  File "c:\users\admin\appdata\local\programs\python\python36\lib\site-packages\flask\helpers.py", line 345, in url_for
    force_external=external)
  File "c:\users\admin\appdata\local\programs\python\python36\lib\site-packages\werkzeug\routing.py", line 1776, in build
    raise BuildError(endpoint, values, method, self)
werkzeug.routing.BuildError: Could not build url for endpoint 'main.search'. Did you mean 'main.user' instead?
2018-10-29 14:44:07,682 INFO: Microblog startup [in C:\Users\admin\Desktop\flask\mega_blog\app\__init__.py:58]
2018-10-29 14:44:14,094 ERROR: Exception on /search [GET] [in c:\users\admin\appdata\local\programs\python\python36\lib\site-packages\flask\app.py:1761]
Traceback (most recent call last):
  File "c:\users\admin\appdata\local\programs\python\python36\lib\site-packages\flask\app.py", line 2292, in wsgi_app
    response = self.full_dispatch_request()
  File "c:\users\admin\appdata\local\programs\python\python36\lib\site-packages\flask\app.py", line 1815, in full_dispatch_request
    rv = self.handle_user_exception(e)
  File "c:\users\admin\appdata\local\programs\python\python36\lib\site-packages\flask\app.py", line 1718, in handle_user_exception
    reraise(exc_type, exc_value, tb)
  File "c:\users\admin\appdata\local\programs\python\python36\lib\site-packages\flask\_compat.py", line 35, in reraise
    raise value
  File "c:\users\admin\appdata\local\programs\python\python36\lib\site-packages\flask\app.py", line 1813, in full_dispatch_request
    rv = self.dispatch_request()
  File "c:\users\admin\appdata\local\programs\python\python36\lib\site-packages\flask\app.py", line 1799, in dispatch_request
    return self.view_functions[rule.endpoint](**req.view_args)
  File "c:\users\admin\appdata\local\programs\python\python36\lib\site-packages\flask_login\utils.py", line 261, in decorated_view
    return func(*args, **kwargs)
  File "C:\Users\admin\Desktop\flask\mega_blog\app\main\views.py", line 110, in search
    posts, total = Post.search(g.search_form.q.data, page,current_app.config['POSTS_PER_PAGE'])
  File "C:\Users\admin\Desktop\flask\mega_blog\app\models.py", line 19, in search
    ids, total = query_index(cls.__tablename__, expression, page, per_page)
  File "C:\Users\admin\Desktop\flask\mega_blog\app\search.py", line 25, in query_index
    'from': (page - 1) * per_page, 'size': per_page})
  File "c:\users\admin\appdata\local\programs\python\python36\lib\site-packages\elasticsearch\client\utils.py", line 76, in _wrapped
    return func(*args, params=params, **kwargs)
  File "c:\users\admin\appdata\local\programs\python\python36\lib\site-packages\elasticsearch\client\__init__.py", line 660, in search
    doc_type, '_search'), params=params, body=body)
  File "c:\users\admin\appdata\local\programs\python\python36\lib\site-packages\elasticsearch\transport.py", line 318, in perform_request
    status, headers_response, data = connection.perform_request(method, url, params, body, headers=headers, ignore=ignore, timeout=timeout)
  File "c:\users\admin\appdata\local\programs\python\python36\lib\site-packages\elasticsearch\connection\http_urllib3.py", line 186, in perform_request
    self._raise_error(response.status, raw_data)
  File "c:\users\admin\appdata\local\programs\python\python36\lib\site-packages\elasticsearch\connection\base.py", line 125, in _raise_error
    raise HTTP_EXCEPTIONS.get(status_code, TransportError)(status_code, error_message, additional_info)
elasticsearch.exceptions.NotFoundError: NotFoundError(404, 'index_not_found_exception', 'no such index')
2018-10-29 14:45:11,462 ERROR: Exception on /search [GET] [in c:\users\admin\appdata\local\programs\python\python36\lib\site-packages\flask\app.py:1761]
Traceback (most recent call last):
  File "c:\users\admin\appdata\local\programs\python\python36\lib\site-packages\flask\app.py", line 2292, in wsgi_app
    response = self.full_dispatch_request()
  File "c:\users\admin\appdata\local\programs\python\python36\lib\site-packages\flask\app.py", line 1815, in full_dispatch_request
    rv = self.handle_user_exception(e)
  File "c:\users\admin\appdata\local\programs\python\python36\lib\site-packages\flask\app.py", line 1718, in handle_user_exception
    reraise(exc_type, exc_value, tb)
  File "c:\users\admin\appdata\local\programs\python\python36\lib\site-packages\flask\_compat.py", line 35, in reraise
    raise value
  File "c:\users\admin\appdata\local\programs\python\python36\lib\site-packages\flask\app.py", line 1813, in full_dispatch_request
    rv = self.dispatch_request()
  File "c:\users\admin\appdata\local\programs\python\python36\lib\site-packages\flask\app.py", line 1799, in dispatch_request
    return self.view_functions[rule.endpoint](**req.view_args)
  File "c:\users\admin\appdata\local\programs\python\python36\lib\site-packages\flask_login\utils.py", line 261, in decorated_view
    return func(*args, **kwargs)
  File "C:\Users\admin\Desktop\flask\mega_blog\app\main\views.py", line 110, in search
    posts, total = Post.search(g.search_form.q.data, page,current_app.config['POSTS_PER_PAGE'])
  File "C:\Users\admin\Desktop\flask\mega_blog\app\models.py", line 21, in search
    return cls.query.filter(id=0), 0
TypeError: filter() got an unexpected keyword argument 'id'
2018-10-29 14:46:09,483 INFO: Microblog startup [in C:\Users\admin\Desktop\flask\mega_blog\app\__init__.py:58]
